Workbook

Sheet Zielliste
A1: Nr | B1: Prio | C1: Unternehmen | D1: Ort | E1: Kanton | F1: Segment | G1: Was sie herstellen / was am Standort läuft | H1: Umsatz (Mio, Orig.) | I1: Whg. | J1: Umsatz CHF Mio | K1: Grössenklasse | L1: GJ | M1: Mitarbeiter | N1: Eigentümer / Kotierung | O1: Datenqualität | P1: Kategorie | Q1: Mandat / Hinweis | R1: Fit-Score (1-5) | S1: Kontakt im Netzwerk | T1: Status | U1: Notizen | V1: Quelle | W1: jobs.ch-Suchbegriff | X1: jobs.ch-Suche | Y1: Karriereseite (geprüft)
A2: 1 | B2: 1 | C2: ABB | D2: Zürich | E2: ZH | F2: Elektrotechnik/Automation | G2: Elektrifizierung, Antriebe, Robotik, Prozessautomation | H2: 33220 | I2: USD | J2: =IF(H2="","",H2*IF(I2="CHF",1,IF(I2="EUR",'Legende & Kriterien'!$C$13,'Legende & Kriterien'!$C$14))) | K2: =IF(P2="Rohstoffhandel","— Handel —",IF(J2="","k.A.",IF(J2>=5000,"A: >5 Mrd.",IF(J2>=3000,"B: 3-5 Mrd.",IF(J2>=1000,"C: 1-3 Mrd.","D: 0.1-1 Mrd."))))) | L2: 2025 | M2: 111900 | N2: SIX + Nasdaq Stockholm: ABBN | O2: publiziert | P2: Grosskonzern | V2: https://www.abb.com/global/en/company/annual-reporting-suite/key-figures | W2: ABB | X2: Stellen suchen | Y2: https://www.jobs.ch/en/companies/55089-abb-schweiz-ag/
A3: 2 | B3: 1 | C3: Amcor | D3: Zürich | E3: ZH | F3: Verpackung | G3: Flexible und starre Verpackungen, Verschlüsse, Spendersysteme | H3: 23506 | I3: USD | J3: =IF(H3="","",H3*IF(I3="CHF",1,IF(I3="EUR",'Legende & Kriterien'!$C$13,'Legende & Kriterien'!$C$14))) | K3: =IF(P3="Rohstoffhandel","— Handel —",IF(J3="","k.A.",IF(J3>=5000,"A: >5 Mrd.",IF(J3>=3000,"B: 3-5 Mrd.",IF(J3>=1000,"C: 1-3 Mrd.","D: 0.1-1 Mrd."))))) | L3: 2025/26 | M3: 75000 | N3: NYSE + ASX: AMCR | O3: publiziert | P3: Grosskonzern | Q3: Jersey-Recht; ab 2027 Verlagerung von Konzernfunktionen nach Miami | V3: https://www.amcor.com/investors | W3: Amcor | X3: Stellen suchen | Y3: https://amcor.wd5.myworkdayjobs.com/Amcor_External_Career_Site — nicht abrufbar ohne Rendern, Workday
A4: 3 | B4: 1 | C4: Hitachi Energy | D4: Zürich | E4: ZH | F4: Energie-/Netztechnik | G4: Transformatoren, HGÜ, Hochspannungsprodukte, Netzautomation | H4: 20000 | I4: USD | J4: =IF(H4="","",H4*IF(I4="CHF",1,IF(I4="EUR",'Legende & Kriterien'!$C$13,'Legende & Kriterien'!$C$14))) | K4: =IF(P4="Rohstoffhandel","— Handel —",IF(J4="","k.A.",IF(J4>=5000,"A: >5 Mrd.",IF(J4>=3000,"B: 3-5 Mrd.",IF(J4>=1000,"C: 1-3 Mrd.","D: 0.1-1 Mrd."))))) | L4: 2026 | M4: 56000 | N4: Hitachi Ltd. (JP), nicht kotiert | O4: geschätzt | P4: Grosskonzern | Q4: Kein separat testierter Abschluss; Zahl ist Unternehmensangabe | V4: https://www.hitachienergy.com/company/company-profile | W4: Hitachi Energy | X4: Stellen suchen | Y4: https://careers.hitachi.com/search/hitachi-energy/jobs/in/country/switzerland
A5: 4 | B5: 1 | C5: Holcim | D5: Zug | E5: ZG | F5: Baustoffe | G5: Zement, Beton, Zuschlagstoffe, Dach- und Dämmsysteme | H5: 15724 | I5: CHF | J5: =IF(H5="","",H5*IF(I5="CHF",1,IF(I5="EUR",'Legende & Kriterien'!$C$13,'Legende & Kriterien'!$C$14))) | K5: =IF(P5="Rohstoffhandel","— Handel —",IF(J5="","k.A.",IF(J5>=5000,"A: >5 Mrd.",IF(J5>=3000,"B: 3-5 Mrd.",IF(J5>=1000,"C: 1-3 Mrd.","D: 0.1-1 Mrd."))))) | L5: 2025 | M5: 45000 | N5: SIX: HOLN | O5: publiziert | P5: Grosskonzern | Q5: Nach Abspaltung von Amrize | V5: https://www.holcim.com/media/media-releases/full-year-2025-results | W5: Holcim | X5: Stellen suchen | Y5: https://careers.holcimgroup.com/search/
A6: 5 | B6: 1 | C6: Liebherr-International | D6: Bulle | E6: FR | F6: Maschinen-/Anlagenbau | G6: Baumaschinen, Krane, Bergbaugeräte, Kühlgeräte, Luftfahrtkomponenten | H6: 14772 | I6: EUR | J6: =IF(H6="","",H6*IF(I6="CHF",1,IF(I6="EUR",'Legende & Kriterien'!$C$13,'Legende & Kriterien'!$C$14))) | K6: =IF(P6="Rohstoffhandel","— Handel —",IF(J6="","k.A.",IF(J6>=5000,"A: >5 Mrd.",IF(J6>=3000,"B: 3-5 Mrd.",IF(J6>=1000,"C: 1-3 Mrd.","D: 0.1-1 Mrd."))))) | L6: 2025 | M6: 55963 | N6: Familie Liebherr, nicht kotiert | O6: publiziert | P6: Grosskonzern | Q6: GB 2025 nennt Nussbaumen AG als Konzernadresse — HQ-Angabe uneinheitlich | V6: https://www.liebherr.com/en-us/n/liebherr-sees-stable-growth-in-the-2025-business-year-244544-3782185 | W6: Liebherr | X6: Stellen suchen | Y6: https://www.liebherr.com/de/deu/karriere/offene-stellen/offene-stellen.html
A7: 6 | B7: 1 | C7: Sika | D7: Baar | E7: ZG | F7: Bauchemie/Spezialchemie | G7: Bauchemie, Klebstoffe, Dichtstoffe, Mörtel, Abdichtungsbahnen | H7: 11201 | I7: CHF | J7: =IF(H7="","",H7*IF(I7="CHF",1,IF(I7="EUR",'Legende & Kriterien'!$C$13,'Legende & Kriterien'!$C$14))) | K7: =IF(P7="Rohstoffhandel","— Handel —",IF(J7="","k.A.",IF(J7>=5000,"A: >5 Mrd.",IF(J7>=3000,"B: 3-5 Mrd.",IF(J7>=1000,"C: 1-3 Mrd.","D: 0.1-1 Mrd."))))) | L7: 2025 | M7: 33707 | N7: SIX: SIKA | O7: publiziert | P7: Grosskonzern | V7: https://www.sika.com/en/media/media-releases/2026/sika-reports-full-year-2025-results.html | W7: Sika | X7: Stellen suchen | Y7: https://www.sika.com/en/career/jobs.html — nicht abrufbar ohne Rendern, JS-Widget
A8: 7 | B8: 1 | C8: Schindler | D8: Ebikon | E8: LU | F8: Gebäudetechnik/Maschinenbau | G8: Aufzüge, Fahrtreppen, Fahrsteige, Modernisierung, Wartung | H8: 10947 | I8: CHF | J8: =IF(H8="","",H8*IF(I8="CHF",1,IF(I8="EUR",'Legende & Kriterien'!$C$13,'Legende & Kriterien'!$C$14))) | K8: =IF(P8="Rohstoffhandel","— Handel —",IF(J8="","k.A.",IF(J8>=5000,"A: >5 Mrd.",IF(J8>=3000,"B: 3-5 Mrd.",IF(J8>=1000,"C: 1-3 Mrd.","D: 0.1-1 Mrd."))))) | L8: 2025 | M8: 67000 | N8: SIX: SCHN/SCHP, Familien Schindler/Bonnard | O8: publiziert | P8: Grosskonzern | V8: https://group.schindler.com/en/media/press-releases/annual-results-2025.html | W8: Schindler | X8: Stellen suchen | Y8: https://job.schindler.com/search/
A9: 8 | B9: 1 | C9: STMicroelectronics | D9: Plan-les-Ouates (Genf) | E9: GE | F9: Halbleiter | G9: Mikrocontroller, Leistungshalbleiter, Sensoren, Analog-Chips | H9: 11800 | I9: USD | J9: =IF(H9="","",H9*IF(I9="CHF",1,IF(I9="EUR",'Legende & Kriterien'!$C$13,'Legende & Kriterien'!$C$14))) | K9: =IF(P9="Rohstoffhandel","— Handel —",IF(J9="","k.A.",IF(J9>=5000,"A: >5 Mrd.",IF(J9>=3000,"B: 3-5 Mrd.",IF(J9>=1000,"C: 1-3 Mrd.","D: 0.1-1 Mrd."))))) | L9: 2025 | M9: 48000 | N9: NYSE / Euronext Paris / Borsa Italiana | O9: publiziert | P9: Grenzfall | Q9: Operativer HQ Genf, statutarischer Sitz Amsterdam (NL) | V9: https://www.globenewswire.com/news-release/2026/01/29/3228178/0/en/STMicroelectronics-Reports-Q4-and-FY-2025-Financial-Results.html | W9: STMicroelectronics | X9: Stellen suchen | Y9: https://stmicroelectronics.eightfold.ai/careers — nicht abrufbar ohne Rendern, Eightfold-SPA
A10: 9 | B10: 1 | C10: Alcon | D10: Genf | E10: GE | F10: Medtech/Ophthalmologie | G10: Intraokularlinsen, Kontaktlinsen, Augenchirurgie-Systeme | H10: 10319 | I10: USD | J10: =IF(H10="","",H10*IF(I10="CHF",1,IF(I10="EUR",'Legende & Kriterien'!$C$13,'Legende & Kriterien'!$C$14))) | K10: =IF(P10="Rohstoffhandel","— Handel —",IF(J10="","k.A.",IF(J10>=5000,"A: >5 Mrd.",IF(J10>=3000,"B: 3-5 Mrd.",IF(J10>=1000,"C: 1-3 Mrd.","D: 0.1-1 Mrd."))))) | L10: 2025 | M10: 25000 | N10: SIX + NYSE: ALC | O10: publiziert | P10: Grosskonzern | Q10: Statutarischer Sitz im Kanton Freiburg | V10: https://www.alcon.com/investor-relations | W10: Alcon | X10: Stellen suchen | Y10: https://alcon.wd5.myworkdayjobs.com/careers_alcon — nicht abrufbar ohne Rendern, Workday
A11: 10 | B11: 1 | C11: SGS | D11: Baar | E11: ZG | F11: Prüf-/Zertifizierungsdienste | G11: Kein Hersteller: Prüfung, Inspektion, Verifizierung, Zertifizierung | H11: 6945 | I11: CHF | J11: =IF(H11="","",H11*IF(I11="CHF",1,IF(I11="EUR",'Legende & Kriterien'!$C$13,'Legende & Kriterien'!$C$14))) | K11: =IF(P11="Rohstoffhandel","— Handel —",IF(J11="","k.A.",IF(J11>=5000,"A: >5 Mrd.",IF(J11>=3000,"B: 3-5 Mrd.",IF(J11>=1000,"C: 1-3 Mrd.","D: 0.1-1 Mrd."))))) | L11: 2025 | M11: 100000 | N11: SIX: SGSN | O11: publiziert | P11: Grenzfall | Q11: Dienstleister, kein Engineered Product — nur zur Vollständigkeit | V11: https://www.sgs.com/en/news/2026/02/2025-full-year-results | W11: SGS | X11: Stellen suchen | Y11: https://careers.smartrecruiters.com/SGS
A12: 11 | B12: 1 | C12: Hilti | D12: Schaan | E12: FL | F12: Bau-/Werkzeugtechnik | G12: Bohr-, Befestigungs- und Messtechnik für die Bauindustrie | H12: 6297 | I12: CHF | J12: =IF(H12="","",H12*IF(I12="CHF",1,IF(I12="EUR",'Legende & Kriterien'!$C$13,'Legende & Kriterien'!$C$14))) | K12: =IF(P12="Rohstoffhandel","— Handel —",IF(J12="","k.A.",IF(J12>=5000,"A: >5 Mrd.",IF(J12>=3000,"B: 3-5 Mrd.",IF(J12>=1000,"C: 1-3 Mrd.","D: 0.1-1 Mrd."))))) | L12: 2025 | M12: 34420 | N12: Martin Hilti Familientreuhänderschaft | O12: publiziert | P12: Liechtenstein | V12: https://www.hilti.group/content/hilti/CP/XX/en/company/media-relations/media-releases/2025-business-result.html | W12: Hilti | X12: Stellen suchen | Y12: https://careers.hilti.group/en-us/jobs/
A13: 12 | B13: 1 | C13: Swatch Group | D13: Biel/Bienne | E13: BE | F13: Uhren/Mikrotechnik | G13: Uhren, Uhrwerke, Schmuck, elektronische Komponenten, Mikromechanik | H13: 6280 | I13: CHF | J13: =IF(H13="","",H13*IF(I13="CHF",1,IF(I13="EUR",'Legende & Kriterien'!$C$13,'Legende & Kriterien'!$C$14))) | K13: =IF(P13="Rohstoffhandel","— Handel —",IF(J13="","k.A.",IF(J13>=5000,"A: >5 Mrd.",IF(J13>=3000,"B: 3-5 Mrd.",IF(J13>=1000,"C: 1-3 Mrd.","D: 0.1-1 Mrd."))))) | L13: 2025 | M13: 31800 | N13: SIX: UHR/UHRN, Familie Hayek | O13: publiziert | P13: Grosskonzern | V13: https://www.swatchgroup.com/en/services/archive/2026/key-figures-2025 | W13: Swatch | X13: Stellen suchen | Y13: https://www.swatchgroup.com/en/job-finder
A14: 13 | B14: 1 | C14: Garmin | D14: Schaffhausen | E14: SH | F14: Elektronik/Navigation | G14: GPS-Navigation, Smartwatches, Avionik, Marine- und Outdoor-Geräte | H14: 7250 | I14: USD | J14: =IF(H14="","",H14*IF(I14="CHF",1,IF(I14="EUR",'Legende & Kriterien'!$C$13,'Legende & Kriterien'!$C$14))) | K14: =IF(P14="Rohstoffhandel","— Handel —",IF(J14="","k.A.",IF(J14>=5000,"A: >5 Mrd.",IF(J14>=3000,"B: 3-5 Mrd.",IF(J14>=1000,"C: 1-3 Mrd.","D: 0.1-1 Mrd."))))) | L14: 2025 | M14: 23000 | N14: NYSE: GRMN | O14: publiziert | P14: Grenzfall | Q14: Statutarischer Sitz Schaffhausen, operativer HQ Olathe (Kansas, USA) | V14: https://www8.garmin.com/aboutGarmin/invRelations/reports/2025_Form_10-K.pdf | W14: Garmin | X14: Stellen suchen | Y14: https://careers.garmin.com/jobs — nicht abrufbar ohne Rendern, JS
A15: 14 | B15: 1 | C15: Georg Fischer (GF) | D15: Schaffhausen | E15: SH | F15: Maschinenbau/Fluidtechnik | G15: Rohrleitungssysteme, Armaturen, Wasserbehandlung, Präzisionsfertigung | H15: 4110 | I15: CHF | J15: =IF(H15="","",H15*IF(I15="CHF",1,IF(I15="EUR",'Legende & Kriterien'!$C$13,'Legende & Kriterien'!$C$14))) | K15: =IF(P15="Rohstoffhandel","— Handel —",IF(J15="","k.A.",IF(J15>=5000,"A: >5 Mrd.",IF(J15>=3000,"B: 3-5 Mrd.",IF(J15>=1000,"C: 1-3 Mrd.","D: 0.1-1 Mrd."))))) | L15: 2025 | M15: 16332 | N15: SIX: GF | O15: publiziert | P15: Grosskonzern | Q15: Machining Solutions 2025 an United Grinding verkauft | V15: https://www.georgfischer.com/content/dam/gfcorp/documents/newsroom/media-releases/annual-report-2025/20260225-ad-hoc-announcement-annual-report-2025-en.pdf | W15: Georg Fischer | X15: Stellen suchen | Y15: https://www.georgfischer.com/content/gfcorp/com/en/career/vacancies.html — nicht abrufbar ohne Rendern, Workday
A16: 15 | B16: 1 | C16: Clariant | D16: Muttenz | E16: BL | F16: Spezialchemie | G16: Spezialchemikalien, Katalysatoren, Adsorbentien, Additive | H16: 3915 | I16: CHF | J16: =IF(H16="","",H16*IF(I16="CHF",1,IF(I16="EUR",'Legende & Kriterien'!$C$13,'Legende & Kriterien'!$C$14))) | K16: =IF(P16="Rohstoffhandel","— Handel —",IF(J16="","k.A.",IF(J16>=5000,"A: >5 Mrd.",IF(J16>=3000,"B: 3-5 Mrd.",IF(J16>=1000,"C: 1-3 Mrd.","D: 0.1-1 Mrd."))))) | L16: 2025 | M16: 10281 | N16: SIX: CLN | O16: publiziert | P16: Grosskonzern | V16: https://www.clariant.com/en/Corporate/News/2026/02/Clariant-delivers-third-year-of-strong-EBITDA-margin-improvement | W16: Clariant | X16: Stellen suchen | Y16: https://careers.clariant.com/search/
A17: 16 | B17: 1 | C17: Logitech | D17: Lausanne | E17: VD | F17: Elektronik/Peripherie | G17: Mäuse, Tastaturen, Headsets, Webcams, Videokonferenzgeräte | H17: 4841 | I17: USD | J17: =IF(H17="","",H17*IF(I17="CHF",1,IF(I17="EUR",'Legende & Kriterien'!$C$13,'Legende & Kriterien'!$C$14))) | K17: =IF(P17="Rohstoffhandel","— Handel —",IF(J17="","k.A.",IF(J17>=5000,"A: >5 Mrd.",IF(J17>=3000,"B: 3-5 Mrd.",IF(J17>=1000,"C: 1-3 Mrd.","D: 0.1-1 Mrd."))))) | L17: 2025/26 | M17: 7300 | N17: SIX + Nasdaq: LOGN/LOGI | O17: publiziert | P17: Grosskonzern | Q17: Doppelsitz Lausanne / San Jose | V17: https://www.businesswire.com/news/home/20260505206276/en/Logitech-Announces-Q4-and-Full-Fiscal-Year-2026-Results | W17: Logitech | X17: Stellen suchen | Y17: https://logitech.wd5.myworkdayjobs.com/en-US/Logitech — nicht abrufbar ohne Rendern, Workday (CH ggf. robots-gesperrt)
A18: 17 | B18: 1 | C18: Endress+Hauser | D18: Reinach | E18: BL | F18: Prozessmesstechnik | G18: Messgeräte für Füllstand, Druck, Durchfluss, Analyse | H18: 4010 | I18: EUR | J18: =IF(H18="","",H18*IF(I18="CHF",1,IF(I18="EUR",'Legende & Kriterien'!$C$13,'Legende & Kriterien'!$C$14))) | K18: =IF(P18="Rohstoffhandel","— Handel —",IF(J18="","k.A.",IF(J18>=5000,"A: >5 Mrd.",IF(J18>=3000,"B: 3-5 Mrd.",IF(J18>=1000,"C: 1-3 Mrd.","D: 0.1-1 Mrd."))))) | L18: 2025 | M18: 18306 | N18: Familie Endress (100%) | O18: publiziert | P18: Grosskonzern | V18: https://www.muehle-mischfutter.de/artikel/endress-hauser-2025-uber-vier-mrd--euro-umsatz | W18: Endress Hauser | X18: Stellen suchen | Y18: https://careers.endress.com/Switzerland/content/search/?locale=en_US — nicht abrufbar ohne Rendern, Cookie-Wall
A19: 18 | B19: 1 | C19: Stadler Rail | D19: Bussnang | E19: TG | F19: Schienenfahrzeugbau | G19: Triebzüge, Trams, Lokomotiven, Signaltechnik, Fahrzeugservice | H19: 3679 | I19: CHF | J19: =IF(H19="","",H19*IF(I19="CHF",1,IF(I19="EUR",'Legende & Kriterien'!$C$13,'Legende & Kriterien'!$C$14))) | K19: =IF(P19="Rohstoffhandel","— Handel —",IF(J19="","k.A.",IF(J19>=5000,"A: >5 Mrd.",IF(J19>=3000,"B: 3-5 Mrd.",IF(J19>=1000,"C: 1-3 Mrd.","D: 0.1-1 Mrd."))))) | L19: 2025 | M19: 17100 | N19: SIX: SRAIL, PCS Holding (P. Spuhler) | O19: publiziert | P19: Grosskonzern | Q19: Rund 6'000 Mitarbeitende in der Schweiz | V19: https://www.stadlerrail.com/en/investors/ | W19: Stadler Rail | X19: Stellen suchen | Y19: https://jobs.stadlerrail.ch/
A20: 19 | B20: 1 | C20: Sonova | D20: Stäfa | E20: ZH | F20: Medizintechnik | G20: Hörgeräte, Cochlea-Implantate, drahtlose Audiosysteme | H20: 3606 | I20: CHF | J20: =IF(H20="","",H20*IF(I20="CHF",1,IF(I20="EUR",'Legende & Kriterien'!$C$13,'Legende & Kriterien'!$C$14))) | K20: =IF(P20="Rohstoffhandel","— Handel —",IF(J20="","k.A.",IF(J20>=5000,"A: >5 Mrd.",IF(J20>=3000,"B: 3-5 Mrd.",IF(J20>=1000,"C: 1-3 Mrd.","D: 0.1-1 Mrd."))))) | L20: 2025/26 | M20: 18000 | N20: SIX: SOON | O20: publiziert | P20: Grosskonzern | V20: https://report.sonova.com/2026/en/startpage | W20: Sonova | X20: Stellen suchen | Y20: https://jobs.sonova.com/go/All-Jobs/4577301/
A21: 20 | B21: 1 | C21: Sulzer | D21: Winterthur | E21: ZH | F21: Maschinenbau/Anlagentechnik | G21: Pumpen, Rührwerke, Trennkolonnen, Strömungsmaschinen und Service | H21: 3555 | I21: CHF | J21: =IF(H21="","",H21*IF(I21="CHF",1,IF(I21="EUR",'Legende & Kriterien'!$C$13,'Legende & Kriterien'!$C$14))) | K21: =IF(P21="Rohstoffhandel","— Handel —",IF(J21="","k.A.",IF(J21>=5000,"A: >5 Mrd.",IF(J21>=3000,"B: 3-5 Mrd.",IF(J21>=1000,"C: 1-3 Mrd.","D: 0.1-1 Mrd."))))) | L21: 2025 | M21: 13526 | N21: SIX: SUN, Grossaktionärin Tiwel | O21: publiziert | P21: Grosskonzern | V21: https://www.sulzer.com/en/-/media/files/news/2026/20260226sulzer-exceeds-chf-550-million-ebitda.pdf | W21: Sulzer | X21: Stellen suchen | Y21: https://sulzer.wd502.myworkdayjobs.com/SulzerJobs — nicht abrufbar ohne Rendern, Workday
A22: 21 | B22: 1 | C22: Mettler-Toledo | D22: Greifensee | E22: ZH | F22: Mess-/Wäge-/Analysetechnik | G22: Präzisionswaagen, Laborinstrumente, Pipetten, Produktinspektionssysteme | H22: 4026 | I22: USD | J22: =IF(H22="","",H22*IF(I22="CHF",1,IF(I22="EUR",'Legende & Kriterien'!$C$13,'Legende & Kriterien'!$C$14))) | K22: =IF(P22="Rohstoffhandel","— Handel —",IF(J22="","k.A.",IF(J22>=5000,"A: >5 Mrd.",IF(J22>=3000,"B: 3-5 Mrd.",IF(J22>=1000,"C: 1-3 Mrd.","D: 0.1-1 Mrd."))))) | L22: 2025 | M22: 18100 | N22: NYSE: MTD | O22: publiziert | P22: Grenzfall | Q22: Delaware-Gesellschaft mit Doppelsitz Greifensee / Columbus (Ohio) | V22: https://investor.mt.com/news/news-details/2026/Mettler-Toledo-International-Inc--Reports-Fourth-Quarter-2025-Results/default.aspx | W22: Mettler-Toledo | X22: Stellen suchen | Y22: https://jobs.mt.com/en/search-jobs
A23: 22 | B23: 1 | C23: Geberit | D23: Rapperswil-Jona | E23: SG | F23: Sanitär-/Gebäudetechnik | G23: Sanitärtechnik, Rohrleitungssysteme, Spülkästen, Badkeramik | H23: 3163 | I23: CHF | J23: =IF(H23="","",H23*IF(I23="CHF",1,IF(I23="EUR",'Legende & Kriterien'!$C$13,'Legende & Kriterien'!$C$14))) | K23: =IF(P23="Rohstoffhandel","— Handel —",IF(J23="","k.A.",IF(J23>=5000,"A: >5 Mrd.",IF(J23>=3000,"B: 3-5 Mrd.",IF(J23>=1000,"C: 1-3 Mrd.","D: 0.1-1 Mrd."))))) | L23: 2025 | M23: 11278 | N23: SIX: GEBN | O23: publiziert | P23: Grosskonzern | V23: https://www.geberit.com/assets/downloads/media-releases/2026/media-release-annual-results-2025.pdf | W23: Geberit | X23: Stellen suchen | Y23: https://www.geberit.ch/karriere/ — nicht abrufbar ohne Rendern, Navigation unklar
A24: 23 | B24: 2 | C24: ams-OSRAM | D24: Premstätten (AT) | E24: – | F24: Halbleiter/Photonik | G24: Optische Sensoren, LEDs, Fahrzeuglampen, Photonik-Bauelemente | H24: 3300 | I24: EUR | J24: =IF(H24="","",H24*IF(I24="CHF",1,IF(I24="EUR",'Legende & Kriterien'!$C$13,'Legende & Kriterien'!$C$14))) | K24: =IF(P24="Rohstoffhandel","— Handel —",IF(J24="","k.A.",IF(J24>=5000,"A: >5 Mrd.",IF(J24>=3000,"B: 3-5 Mrd.",IF(J24>=1000,"C: 1-3 Mrd.","D: 0.1-1 Mrd."))))) | L24: 2025 | M24: 18500 | N24: SIX: AMS | O24: publiziert | P24: Grenzfall | Q24: Sitz Österreich — nur an der SIX kotiert | V24: https://ams-osram.com/press/corporate-info | W24: ams-OSRAM | X24: Stellen suchen
A25: 24 | B25: 2 | C25: SFS Group | D25: Heerbrugg (Widnau) | E25: SG | F25: Präzisionsteile/Verbindungstechnik | G25: Präzisionsformteile, Befestigungssysteme, medizintechnische Komponenten | H25: 3057 | I25: CHF | J25: =IF(H25="","",H25*IF(I25="CHF",1,IF(I25="EUR",'Legende & Kriterien'!$C$13,'Legende & Kriterien'!$C$14))) | K25: =IF(P25="Rohstoffhandel","— Handel —",IF(J25="","k.A.",IF(J25>=5000,"A: >5 Mrd.",IF(J25>=3000,"B: 3-5 Mrd.",IF(J25>=1000,"C: 1-3 Mrd.","D: 0.1-1 Mrd."))))) | L25: 2025 | M25: 13600 | N25: SIX: SFSN, Familienaktionariat | O25: publiziert | P25: Grosskonzern | V25: https://www.sfs.com/ch/en/sfs-group/sfs-at-a-glance/ | W25: SFS | X25: Stellen suchen
A26: 25 | B26: 2 | C26: SIG Group | D26: Neuhausen a. Rhf. | E26: SH | F26: Verpackungssysteme | G26: Aseptische Kartonverpackungen, Beutel, Abfüllmaschinen | H26: 3249 | I26: EUR | J26: =IF(H26="","",H26*IF(I26="CHF",1,IF(I26="EUR",'Legende & Kriterien'!$C$13,'Legende & Kriterien'!$C$14))) | K26: =IF(P26="Rohstoffhandel","— Handel —",IF(J26="","k.A.",IF(J26>=5000,"A: >5 Mrd.",IF(J26>=3000,"B: 3-5 Mrd.",IF(J26>=1000,"C: 1-3 Mrd.","D: 0.1-1 Mrd."))))) | L26: 2025 | M26: 9700 | N26: SIX: SIGN | O26: publiziert | P26: Grosskonzern | V26: https://www.sig.biz/investors | W26: SIG | X26: Stellen suchen
A27: 26 | B27: 1 | C27: Bucher Industries | D27: Niederweningen | E27: ZH | F27: Maschinenbau | G27: Landmaschinen, Kommunalfahrzeuge, Hydraulik, Glasanlagen | H27: 2914 | I27: CHF | J27: =IF(H27="","",H27*IF(I27="CHF",1,IF(I27="EUR",'Legende & Kriterien'!$C$13,'Legende & Kriterien'!$C$14))) | K27: =IF(P27="Rohstoffhandel","— Handel —",IF(J27="","k.A.",IF(J27>=5000,"A: >5 Mrd.",IF(J27>=3000,"B: 3-5 Mrd.",IF(J27>=1000,"C: 1-3 Mrd.","D: 0.1-1 Mrd."))))) | L27: 2025 | M27: 12700 | N27: SIX: BUCN | O27: publiziert | P27: im Band | V27: https://stockanalysis.com/quote/swx/BUCN/financials/ | W27: Bucher Municipal | X27: Stellen suchen | Y27: https://www.bucherindustries.com/en/career/vacancies — nicht abrufbar ohne Rendern, keine Konzernliste
A28: 27 | B28: 2 | C28: dormakaba | D28: Rümlang | E28: ZH | F28: Sicherheitstechnik | G28: Türtechnik, Schliesssysteme, Zutrittskontrolle | H28: 2870 | I28: CHF | J28: =IF(H28="","",H28*IF(I28="CHF",1,IF(I28="EUR",'Legende & Kriterien'!$C$13,'Legende & Kriterien'!$C$14))) | K28: =IF(P28="Rohstoffhandel","— Handel —",IF(J28="","k.A.",IF(J28>=5000,"A: >5 Mrd.",IF(J28>=3000,"B: 3-5 Mrd.",IF(J28>=1000,"C: 1-3 Mrd.","D: 0.1-1 Mrd."))))) | L28: 2024/25 | M28: 15400 | N28: SIX: DOKA | O28: publiziert | P28: im Band | V28: https://stockanalysis.com/quote/swx/DOKA/financials/ | W28: dormakaba | X28: Stellen suchen
A29: 28 | B29: 1 | C29: Bühler Group | D29: Uzwil | E29: SG | F29: Verfahrenstechnik | G29: Anlagen für Getreide-, Lebensmittel- und Materialverarbeitung, Druckguss | H29: 2753 | I29: CHF | J29: =IF(H29="","",H29*IF(I29="CHF",1,IF(I29="EUR",'Legende & Kriterien'!$C$13,'Legende & Kriterien'!$C$14))) | K29: =IF(P29="Rohstoffhandel","— Handel —",IF(J29="","k.A.",IF(J29>=5000,"A: >5 Mrd.",IF(J29>=3000,"B: 3-5 Mrd.",IF(J29>=1000,"C: 1-3 Mrd.","D: 0.1-1 Mrd."))))) | L29: 2025 | M29: 12300 | N29: Familie Bühler (100%) | O29: publiziert | P29: im Band | V29: https://www.moneycab.com/schweiz/buehler-buesst-2025-an-umsatz-ein/ | W29: Bühler | X29: Stellen suchen | Y29: https://www.buhlergroup.com/global/en/careers/jobs.html — nicht abrufbar ohne Rendern, JS
A30: 29 | B30: 3 | C30: Straumann | D30: Basel | E30: BS | F30: Medtech/Dental | G30: Dentalimplantate, Prothetik, digitale Kieferorthopädie | H30: 2605 | I30: CHF | J30: =IF(H30="","",H30*IF(I30="CHF",1,IF(I30="EUR",'Legende & Kriterien'!$C$13,'Legende & Kriterien'!$C$14))) | K30: =IF(P30="Rohstoffhandel","— Handel —",IF(J30="","k.A.",IF(J30>=5000,"A: >5 Mrd.",IF(J30>=3000,"B: 3-5 Mrd.",IF(J30>=1000,"C: 1-3 Mrd.","D: 0.1-1 Mrd."))))) | L30: 2025 | M30: 11800 | N30: SIX: STMN | O30: publiziert | P30: im Band | V30: https://stockanalysis.com/quote/swx/STMN/financials/ | W30: Straumann | X30: Stellen suchen
A31: 30 | B31: 3 | C31: Franke Group (Artemis) | D31: Aarburg | E31: AG | F31: Gebäudetechnik/Foodservice | G31: Küchensysteme, Grossküchentechnik, professionelle Kaffeemaschinen | H31: 2420 | I31: CHF | J31: =IF(H31="","",H31*IF(I31="CHF",1,IF(I31="EUR",'Legende & Kriterien'!$C$13,'Legende & Kriterien'!$C$14))) | K31: =IF(P31="Rohstoffhandel","— Handel —",IF(J31="","k.A.",IF(J31>=5000,"A: >5 Mrd.",IF(J31>=3000,"B: 3-5 Mrd.",IF(J31>=1000,"C: 1-3 Mrd.","D: 0.1-1 Mrd."))))) | L31: 2023 | M31: 8000 | N31: Familie Pieper (Artemis) | O31: veraltet | P31: im Band | Q31: Artemis-Gruppe gesamt CHF 2.88 Mrd. (2025) | V31: https://www.franke.com/de/de/gruppe/medien/2024/artemis-group-results-2024.html | W31: Franke | X31: Stellen suchen
A32: 31 | B32: 3 | C32: Swiss Steel | D32: Emmenbrücke | E32: LU | F32: Stahl/Materialien | G32: Spezialstahl-Langprodukte, Werkzeugstahl, Blankstahl | H32: 2511 | I32: EUR | J32: =IF(H32="","",H32*IF(I32="CHF",1,IF(I32="EUR",'Legende & Kriterien'!$C$13,'Legende & Kriterien'!$C$14))) | K32: =IF(P32="Rohstoffhandel","— Handel —",IF(J32="","k.A.",IF(J32>=5000,"A: >5 Mrd.",IF(J32>=3000,"B: 3-5 Mrd.",IF(J32>=1000,"C: 1-3 Mrd.","D: 0.1-1 Mrd."))))) | L32: 2024 | M32: 7450 | N32: SIX: STLN | O32: veraltet | P32: im Band | Q32: GJ 2025 nicht bestätigt | V32: https://stockanalysis.com/quote/swx/STLN/revenue/ | W32: Swiss Steel | X32: Stellen suchen
A33: 32 | B33: 3 | C33: Autoneum | D33: Winterthur | E33: ZH | F33: Automobilkomponenten | G33: Akustik- und Wärmedämmkomponenten für Fahrzeuge | H33: 2291 | I33: CHF | J33: =IF(H33="","",H33*IF(I33="CHF",1,IF(I33="EUR",'Legende & Kriterien'!$C$13,'Legende & Kriterien'!$C$14))) | K33: =IF(P33="Rohstoffhandel","— Handel —",IF(J33="","k.A.",IF(J33>=5000,"A: >5 Mrd.",IF(J33>=3000,"B: 3-5 Mrd.",IF(J33>=1000,"C: 1-3 Mrd.","D: 0.1-1 Mrd."))))) | L33: 2025 | M33: 16100 | N33: SIX: AUTN | O33: publiziert | P33: im Band | V33: https://stockanalysis.com/quote/swx/AUTN/financials/ | W33: Autoneum | X33: Stellen suchen
A34: 33 | B34: 3 | C34: EMS-CHEMIE | D34: Domat/Ems | E34: GR | F34: Materialien | G34: Hochleistungspolymere und Polyamide für Leichtbauteile | H34: 1969 | I34: CHF | J34: =IF(H34="","",H34*IF(I34="CHF",1,IF(I34="EUR",'Legende & Kriterien'!$C$13,'Legende & Kriterien'!$C$14))) | K34: =IF(P34="Rohstoffhandel","— Handel —",IF(J34="","k.A.",IF(J34>=5000,"A: >5 Mrd.",IF(J34>=3000,"B: 3-5 Mrd.",IF(J34>=1000,"C: 1-3 Mrd.","D: 0.1-1 Mrd."))))) | L34: 2025 | M34: 2660 | N34: SIX: EMSN | O34: publiziert | P34: im Band | V34: https://stockanalysis.com/quote/swx/EMSN/financials/ | W34: EMS-CHEMIE | X34: Stellen suchen
A35: 34 | B35: 3 | C35: Bobst Group | D35: Mex | E35: VD | F35: Verpackungsmaschinen | G35: Maschinen für Faltschachtel-, Wellpappe- und Etikettendruck | H35: 1800 | I35: CHF | J35: =IF(H35="","",H35*IF(I35="CHF",1,IF(I35="EUR",'Legende & Kriterien'!$C$13,'Legende & Kriterien'!$C$14))) | K35: =IF(P35="Rohstoffhandel","— Handel —",IF(J35="","k.A.",IF(J35>=5000,"A: >5 Mrd.",IF(J35>=3000,"B: 3-5 Mrd.",IF(J35>=1000,"C: 1-3 Mrd.","D: 0.1-1 Mrd."))))) | L35: 2024 | M35: 6000 | N35: Privat (Familie Bobst) | O35: geschätzt | P35: im Band | Q35: Dez. 2022 von der SIX dekotiert | V35: https://www.bobst.com/ | W35: Bobst Group | X35: Stellen suchen
A36: 35 | B36: 3 | C36: Pilatus Flugzeugwerke | D36: Stans | E36: NW | F36: Luftfahrt | G36: Trainings- und Geschäftsflugzeuge PC-12, PC-24, PC-21 | H36: 1672 | I36: CHF | J36: =IF(H36="","",H36*IF(I36="CHF",1,IF(I36="EUR",'Legende & Kriterien'!$C$13,'Legende & Kriterien'!$C$14))) | K36: =IF(P36="Rohstoffhandel","— Handel —",IF(J36="","k.A.",IF(J36>=5000,"A: >5 Mrd.",IF(J36>=3000,"B: 3-5 Mrd.",IF(J36>=1000,"C: 1-3 Mrd.","D: 0.1-1 Mrd."))))) | L36: 2025 | M36: 3678 | N36: Privat, CH-Aktionariat | O36: publiziert | P36: im Band | V36: https://www.pilatus-aircraft.com/assets/files/PDF/GB-2025/Pilatus-Geschaeftsbericht-2025.pdf | W36: Pilatus | X36: Stellen suchen
A37: 36 | B37: 1 | C37: Stäubli International | D37: Pfäffikon SZ | E37: SZ | F37: Automation/Robotik | G37: Industrieroboter, Schnellkupplungen, Steckverbinder, Webmaschinen | H37: 1600 | I37: CHF | J37: =IF(H37="","",H37*IF(I37="CHF",1,IF(I37="EUR",'Legende & Kriterien'!$C$13,'Legende & Kriterien'!$C$14))) | K37: =IF(P37="Rohstoffhandel","— Handel —",IF(J37="","k.A.",IF(J37>=5000,"A: >5 Mrd.",IF(J37>=3000,"B: 3-5 Mrd.",IF(J37>=1000,"C: 1-3 Mrd.","D: 0.1-1 Mrd."))))) | L37: 2024 | M37: 6000 | N37: Privat (Familienbesitz) | O37: geschätzt | P37: im Band | Q37: Publiziert keine Zahlen | V37: https://www.staubli.com/ch/de/home.html | W37: Stäubli | X37: Stellen suchen | Y37: https://careers.smartrecruiters.com/staubligroup
A38: 37 | B38: 3 | C38: OC Oerlikon | D38: Pfäffikon SZ | E38: SZ | F38: Materialien/Maschinenbau | G38: Oberflächenbeschichtungen, Polymerverarbeitungsanlagen | H38: 1568 | I38: CHF | J38: =IF(H38="","",H38*IF(I38="CHF",1,IF(I38="EUR",'Legende & Kriterien'!$C$13,'Legende & Kriterien'!$C$14))) | K38: =IF(P38="Rohstoffhandel","— Handel —",IF(J38="","k.A.",IF(J38>=5000,"A: >5 Mrd.",IF(J38>=3000,"B: 3-5 Mrd.",IF(J38>=1000,"C: 1-3 Mrd.","D: 0.1-1 Mrd."))))) | L38: 2025 | M38: 9290 | N38: SIX: OERL | O38: publiziert | P38: im Band | V38: https://stockanalysis.com/quote/swx/OERL/financials/ | W38: OC Oerlikon | X38: Stellen suchen
A39: 38 | B39: 3 | C39: Aebi Schmidt Group | D39: Frauenfeld | E39: TG | F39: Spezialfahrzeuge | G39: Winterdienst-, Kehr- und Spezialfahrzeuge, Nutzfahrzeugaufbauten | H39: 1900 | I39: USD | J39: =IF(H39="","",H39*IF(I39="CHF",1,IF(I39="EUR",'Legende & Kriterien'!$C$13,'Legende & Kriterien'!$C$14))) | K39: =IF(P39="Rohstoffhandel","— Handel —",IF(J39="","k.A.",IF(J39>=5000,"A: >5 Mrd.",IF(J39>=3000,"B: 3-5 Mrd.",IF(J39>=1000,"C: 1-3 Mrd.","D: 0.1-1 Mrd."))))) | L39: 2025 | M39: 6000 | N39: Nasdaq: AEBI (seit 07/2025) | O39: publiziert | P39: im Band | Q39: Fusion mit The Shyft Group 2025; CH-Sitz bestätigt | V39: https://www.aebi-schmidt.com/en/investors | W39: Aebi Schmidt | X39: Stellen suchen
A40: 39 | B40: 2 | C40: UNITED GRINDING Group | D40: Bern | E40: BE | F40: Werkzeugmaschinen | G40: Schleif-, Erodier- und Lasermaschinen (Studer, Walter, Blohm, GFMS) | H40: 1500 | I40: CHF | J40: =IF(H40="","",H40*IF(I40="CHF",1,IF(I40="EUR",'Legende & Kriterien'!$C$13,'Legende & Kriterien'!$C$14))) | K40: =IF(P40="Rohstoffhandel","— Handel —",IF(J40="","k.A.",IF(J40>=5000,"A: >5 Mrd.",IF(J40>=3000,"B: 3-5 Mrd.",IF(J40>=1000,"C: 1-3 Mrd.","D: 0.1-1 Mrd."))))) | L40: 2025 | M40: 4000 | N40: Patinex AG (M. Ebner) | O40: geschätzt | P40: im Band | Q40: GF Machining Solutions per 30.06.2025 übernommen | V40: https://www.grinding.ch/ | W40: United Grinding | X40: Stellen suchen
...

Sheet Legende & Kriterien
A1: Zielliste Schweizer Industrieunternehmen
A2: Stand 28.08.2026 · Kernliste nach Umsatz, danach Konzern-HQs, zuletzt Rohstoffhändler
A4: Die fünf Gruppen
A5: Kern (weiss) | B5: Eigenständige Schweizer Industrieunternehmen mit engineered product, CHF 100 Mio.–3 Mrd.
A6: Grosskonzern (grün) | B6: Schweizer Konzerne über CHF 3 Mrd.
A7: Liechtenstein (orange) | B7: Sitz im Fürstentum. Eigenes Arbeitsrecht und Sozialsystem, ab Meilen nur mit Wochenaufenthalt.
A8: Konzern-HQ CH (violett) | B8: Ausländische Gruppen, deren Schweizer Standort ein internationales Mandat hat. Spalte Q nennt das Mandat.
A9: Rohstoffhandel (grau) | B9: Kein eigenes Produkt. Umsatz ist Handelsumsatz. Nur über die Strategie- und M&A-Schiene relevant.
A11: Mandat (Spalte Q, nur bei violetten Zeilen)
A12: GLOBAL-HQ | B12: Weltzentrale des Konzerns oder der Gruppe sitzt in der Schweiz. Höchste Entscheidungsdichte.
A13: DIVISIONS-HQ | B13: Weltsitz einer einzelnen Division. Für Commercial-Rollen oft ideal: internationales Mandat, überschaubare Organisation.
A14: EMEA-HQ | B14: Europa-/Nahost-/Afrika-Zentrale. Internationales Mandat, aber die Konzernstrategie kommt aus dem Ausland.
A15: GROSSSTANDORT | B15: Grosses Werk oder Entwicklungszentrum ohne HQ-Mandat. Kommerziell meist dünn — vor allem Technik.
A17: Grössenklassen und Wechselkurse
A18: A >5 Mrd. · B 3–5 Mrd. · C 1–3 Mrd. · D 0.1–1 Mrd. Bei Konzern-HQs und Rohstoffhändlern ist die Klasse nicht aussagekräftig — dort zählt die Mitarbeiterzahl in Spalte M.
B20: EUR → CHF | C20: 0.94
B21: USD → CHF | C21: 0.8
A23: Prio-Stufen (Spalte B) — steuern den Job-Radar
A24: Prio 1 | B24: Täglich abgefragt, blau hinterlegt.
A25: Prio 2 | B25: Montag, Mittwoch, Freitag.
A26: Prio 3 | B26: Erster und dritter Dienstag. Alle Neuzugänge stehen zunächst hier.
A28: Datenqualität (Spalte O)
A29: publiziert | B29: Aus Geschäftsbericht oder Medienmitteilung des laufenden Jahres.
A30: veraltet | B30: Letzte öffentlich auffindbare Zahl, teils Jahre alt.
A31: geschätzt | B31: Firma publiziert keine Zahlen. Grössenordnung aus Branchenquellen. Nie zitieren.
A32: Handelsumsatz | B32: Nur bei Rohstoffhändlern. Durchgehandeltes Volumen, keine Wertschöpfung.
A34: Spalten zum Ausfüllen (gelb)
A35: R — Fit-Score | B35: 1–5. 5 = würde ich sofort ansprechen.
A36: S — Kontakt im Netzwerk | B36: Name, wenn du dort jemanden kennst. Die wichtigste Spalte im Blatt.
A37: T — Status | B37: offen / recherchiert / kontaktiert / beworben / abgesagt
A38: U — Notizen | B38: Auslöser, Gesprächsnotizen, offene Stellen.
A40: Was diese Liste nicht ist
A41: Ein Screening-Ausgangspunkt, keine geprüfte Datenbank. Bei den Konzern-HQs sind die Mitarbeiterzahlen meist Schätzungen, und ein Mandat kann sich mit jeder Konzernreorganisation verschieben. Vor jedem Erstkontakt einzeln nachrecherchieren.

Sheet Ausgeschlossen
A1: Grund | B1: Unternehmen
A2: Pharma & Life Sciences | B2: Roche, Novartis, Lonza, Bachem, Siegfried, PolyPeptide — Wirkstoffentwicklung und CDMO, kein Engineered Product.
A3: Lebensmittel & Ingredients | B3: Nestlé, Barry Callebaut, Givaudan, dsm-firmenich, Emmi, Lindt — Nahrungsmittel bzw. Aroma- und Nährstoffchemie.
A4: Dienstleistungen, Handel, Software | B4: Adecco, Kühne+Nagel, ALSO Holding, Implenia, Burkhalter, Kudelski, Dufry — kein eigenes technisches Produkt. SGS ist als Grenzfall in der Hauptliste geführt.
A5: Rohstoffhandel | B5: Glencore, Trafigura, Bunge — Handel und Verarbeitung, keine Industriegüter.
A6: Sitz Liechtenstein, nicht Schweiz | B6: Hilti (Schaan), Ivoclar (Schaan), thyssenkrupp Presta (Eschen), Hoval (Vaduz).
A7: Sitz im Ausland trotz Schweizer Ruf | B7: TE Connectivity (Irland), Precipart (USA), Mubea (DE), Almatec (DE), Autoliv (SE). ams-OSRAM (Österreich) und STMicroelectronics (Amsterdam) sind als Grenzfälle in der Hauptliste.
A8: Unter CHF 100 Mio. Umsatz | B8: Contrinex (~CHF 60–65 Mio.), Datacolor (~CHF 86 Mio.), Agathon, Wandfluh, Regloplas, Sylvac, Bachofen, Gerber Instruments, Jansen (Zahl unbestätigt).
A9: Status unklar oder entfallen | B9: Meyer Burger (Insolvenz von Tochtergesellschaften), Saurer (Konzernmutter chinesisch), Schleuniger (in Komax aufgegangen).
A10: Geprüft, aber nur Landesgesellschaft | B10: Bosch (Zuchwil), Bosch Rexroth, Schaeffler, ZF, Mahle, WAGO, Festo, Rockwell, Atlas Copco, SKF, Kongsberg, Vestas, Nordex, Thales, Leonardo, BAE, Collins Aerospace, Nidec (Birmenstorf), Demant, WSAudiology, Siemens Healthineers, Philips, GE HealthCare, Agilent, Waters, Sartorius, Revvity, ASML, Lam Research, Applied Materials — kein internationales Mandat am Schweizer Standort belegbar.
A11: Sonderfälle | B11: TE Connectivity: Sitz 2024 nach Irland verlegt, verbleibendes Regionalmandat in Schaffhausen nicht belegbar. Alcon und SHL Medical: Schweizer Gesellschaften, kein ausländischer Mutterkonzern — Alcon steht bereits in der Hauptliste. Roche Diagnostics Rotkreuz: Mutterkonzern schweizerisch. TDK-Micronas: Sitz Freiburg im Breisgau, nicht Fribourg.
